package test

import org.scalatest.Spec
import java.io.IOException

sealed class ExceptionTest extends Spec {
  
  private val ThrowRuntimeEx = 1
  private val ThrowIllegalArgEx = 2
  private val ThrowIoEx = 3
  
  sealed class Tester {
    private var _runtimeEx = false
    private var _illegalArgEx = false
    private var _ioEx = false
    private var _finally = false
    
    def runtimeExCaught = _runtimeEx
    def illegalArgExCaught = _illegalArgEx
    def ioExCaught = _ioEx
    def finallyInvoked = _finally
    
    def run(choice: Int) = {
      try {
        choice match {
          case `ThrowRuntimeEx` => throw new RuntimeException
          case `ThrowIllegalArgEx` => throw new IllegalArgumentException
          case `ThrowIoEx` => throw new IOException
        }
      } catch {
        case ex: IllegalArgumentException => _illegalArgEx = true
        case ex: RuntimeException => _runtimeEx = true
      } //catch
      finally {
        _finally = true
      }//finally
    }//run
  }
  
  object `demo usage` {
    
    def safeDivide(x: Int,y: Int) = {
      try{
        Some(x/y)
      } catch {
        case _: ArithmeticException => None
      }// case
    }// safeDivide
    
    def `demo catch` = {
      assertResult(2)(safeDivide(5, 2).get)
      assert(safeDivide(6, 0).isEmpty)
    }
    
    def `throw sub exception` = {
      val t = new Tester
      t.run(ThrowIllegalArgEx)
      assert(t.illegalArgExCaught)
      assert(!t.runtimeExCaught)
      assert(!t.ioExCaught)
      assert(t.finallyInvoked)
    }

    /*
    def `throw super exception` = {
      _fool(ThrowRuntimeEx)
      assert(!_illegalArgEx)
      assert(_runtimeEx)
      assert(!_ioEx)
      assert(_finally)
    }
    
    def `throw runtime exception` = {
      _fool(-100000000)
      assert(!_illegalArgEx)
      assert(_runtimeEx)// because MatchError belongs to "RuntimeException"
      assert(!_ioEx)
      assert(_finally)
    }

    def `auto propagate up` = {
      intercept[IOException] { _fool(ThrowIoEx) }
      assert(_finally)
    }

    def `catch propagated exception outside` {
      try {
        _fool(ThrowIoEx)
        fail("should never run this line")
      } catch {
        case ex: IOException => _ioEx = true
      }
      assert(_finally)
      assert(_ioEx)
    }
    * 
    */
    
  }

}